ERROR:ex:Error!
Traceback (most recent call last):
  File "log_1.py", line 5, in <module>
    raise RuntimeError
RuntimeError
